<?xml version="1.0" encoding="utf-8"?>
<!-- This URDF was automatically created by SolidWorks to URDF Exporter! Originally created by Stephen Brawner (brawner@gmail.com) 
     Commit Version: 1.6.0-1-g15f4949  Build Version: 1.6.7594.29634
     For more information, please see http://wiki.ros.org/sw_urdf_exporter -->
<robot name="hi">

  <!-- ************************************************************ -->
  <!-- ************************ Base ************************** -->
  <!-- ************************************************************ -->
  <mujoco>
    <compiler meshdir="../meshes/" discardvisual="false" balanceinertia="true" />
  </mujoco>
  <!-- [CAUTION] uncomment when convert to mujoco -->
  <!-- <link name="world"></link>
  <joint name="floating_base_joint" type="floating">
    <parent link="world"/>
    <child link="base_link"/>
  </joint> -->

  <link name="base_link">
    <inertial>
      <origin xyz="-0.00066928 -4.5533E-05 0.16942" rpy="0 0 0" />
      <mass value="19.704" />
      <inertia ixx="0.385" ixy="0.000" ixz="-0.002"
               iyy="0.301" iyz="0.000" izz="0.141" />
    </inertial>
    <visual>
      <origin xyz="0 0 0" rpy="0 0 0" />
      <geometry>
        <mesh filename="../meshes/TORSO.STL" />
      </geometry>
      <material name="">
        <color rgba="0.49804 0.49804 0.49804 1" />
      </material>
    </visual>
     <collision>
      <origin
        xyz="0 0 0"
        rpy="0 0 0" />
      <geometry>
        <mesh
          filename="../meshes/TORSO.STL" />
      </geometry>
    </collision>
  </link>

  <!-- ************************************************************ -->
  <!-- ************************ Left Arm ************************** -->
  <!-- ************************************************************ -->
  <link name="left_shoulder_pitch_link">
    <inertial>
      <origin
        xyz="0.00400263772227397 0.0697880160520229 0.000251205468202231"
        rpy="0 0 0" />
      <mass
        value="1.26939754547978" />
      <inertia
        ixx="0.001" ixy="-0.00" ixz="-0.00"
        iyy="0.001" iyz="-0.00" izz="0.001" />
    </inertial>
    <visual>
      <origin
        xyz="0 0 0"
        rpy="0 0 0" />
      <geometry>
        <mesh
          filename="../meshes/SCAPULA_L.STL" />
      </geometry>
      <material
        name="">
        <color
          rgba="0.698039215686274 0.698039215686274 0.698039215686274 1" />
      </material>
    </visual>
     <collision>
      <origin
        xyz="0 0 0"
        rpy="0 0 0" />
      <geometry>
        <mesh
          filename="../meshes/SCAPULA_L.STL" />
      </geometry>
    </collision>
  </link>
  <joint name="left_shoulder_pitch_joint" type="revolute">
    <origin
      xyz="0 0.15869 0.29644"
      rpy="0.34907 0 0" />
    <parent
      link="base_link" />
    <child
      link="left_shoulder_pitch_link" />
    <axis
      xyz="0 1 0" />
    <limit
      lower="-3.31"
      upper="1.22"
      effort="57"
      velocity="3.56" />
  </joint>

  <link name="left_shoulder_roll_link">
    <inertial>
      <origin xyz="-0.000181357466442447 0.000167995164752133 -0.082367684836536" rpy="0 0 0" />
      <mass value="1.38240689883825" />
      <inertia
        ixx="0.003" ixy="0.00" ixz="0.00"
        iyy="0.004" iyz="0.00" izz="0.001" />
    </inertial>
    <visual>
      <origin
        xyz="0 0 0"
        rpy="0 0 0" />
      <geometry>
        <mesh
          filename="../meshes/SHOULDER_L.STL" />
      </geometry>
      <material
        name="">
        <color
          rgba="0.898039215686275 0.917647058823529 0.929411764705882 1" />
      </material>
    </visual>
     <collision>
      <origin
        xyz="0 0 0"
        rpy="0 0 0" />
      <geometry>
        <mesh
          filename="../meshes/SHOULDER_L.STL" />
      </geometry>
    </collision>
  </link>
  <joint name="left_shoulder_roll_joint" type="revolute">
    <origin
      xyz="0 0.075202 0"
      rpy="-0.34907 0 0" />
    <parent
      link="left_shoulder_pitch_link" />
    <child
      link="left_shoulder_roll_link" />
    <axis
      xyz="1 0 0" />
    <limit
      lower="-0.1"
      upper="3.14"
      effort="57"
      velocity="3.56" />
  </joint>

  <link name="left_shoulder_yaw_link">
    <inertial>
      <origin xyz="7.48440000580969E-05 0.000973181848945098 -0.119564156853037" rpy="0 0 0" />
      <mass value="1.15205466163188" />
      <inertia ixx="0.003" ixy="0.00" ixz="0.00"
        iyy="0.003" iyz="0.00" izz="0.001" />
    </inertial>
    <visual>
      <origin
        xyz="0 0 0"
        rpy="0 0 0" />
      <geometry>
        <mesh
          filename="../meshes/UPPERARM_L.STL" />
      </geometry>
      <material
        name="">
        <color
          rgba="0.898039215686275 0.917647058823529 0.929411764705882 1" />
      </material>
    </visual>
     <collision>
      <origin
        xyz="0 0 0"
        rpy="0 0 0" />
      <geometry>
        <mesh
          filename="../meshes/UPPERARM_L.STL" />
      </geometry>
    </collision>
  </link>
  <joint name="left_shoulder_yaw_joint" type="revolute">
    <origin
      xyz="0 0 -0.0845"
      rpy="0 0 0" />
    <parent
      link="left_shoulder_roll_link" />
    <child
      link="left_shoulder_yaw_link" />
    <axis
      xyz="0 0 1" />
    <limit
      lower="-2.94"
      upper="2.94"
      effort="57"
      velocity="3.56" />
  </joint>

  <link name="left_elbow_link">
    <inertial>
      <origin xyz="-0.00053880141083168 0.000598633712610014 -0.0750633848858426" rpy="0 0 0" />
      <mass value="0.962923504066897" />
      <inertia
        ixx="0.002" ixy="0.00" ixz="0.00"
        iyy="0.002" iyz="0.00" izz="0.001" />
    </inertial>
    <visual>
      <origin
        xyz="0 0 0"
        rpy="0 0 0" />
      <geometry>
        <mesh
          filename="../meshes/FOREARM_L.STL" />
      </geometry>
      <material
        name="">
        <color
          rgba="0.898039215686275 0.917647058823529 0.929411764705882 1" />
      </material>
    </visual>
     <collision>
      <origin
        xyz="0 0 0"
        rpy="0 0 0" />
      <geometry>
        <mesh
          filename="../meshes/FOREARM_L.STL" />
      </geometry>
    </collision>
  </link>
  <joint name="left_elbow_joint" type="revolute">
    <origin
      xyz="0 0 -0.1455"
      rpy="0 0 0" />
    <parent
      link="left_shoulder_yaw_link" />
    <child
      link="left_elbow_link" />
    <axis
      xyz="0 1 0" />
    <limit
      lower="-2.09"
      upper="-0.2"
      effort="31"
      velocity="3.66" />
  </joint>

  <link name="left_wrist_yaw_link">
    <inertial>
      <origin xyz="0.000421442405164577 0.000436043607219078 -0.106091587175541" rpy="0 0 0" />
      <mass value="0.816182731607584" />
      <inertia
        ixx="0.003" ixy="0.00" ixz="0.00"
        iyy="0.003" iyz="0.00" izz="0.001" />
    </inertial>
    <visual>
      <origin
        xyz="0 0 0"
        rpy="0 0 0" />
      <geometry>
        <mesh
          filename="../meshes/WRIST_REVOLUTE_L.STL" />
      </geometry>
      <material
        name="">
        <color
          rgba="0.898039215686275 0.917647058823529 0.929411764705882 1" />
      </material>
    </visual>
     <collision>
      <origin
        xyz="0 0 0"
        rpy="0 0 0" />
      <geometry>
        <mesh
          filename="../meshes/WRIST_REVOLUTE_L.STL" />
      </geometry>
    </collision>
  </link>
  <joint name="left_wrist_yaw_joint" type="fixed">
    <origin
      xyz="0 0 -0.068424"
      rpy="0 0 0" />
    <parent
      link="left_elbow_link" />
    <child
      link="left_wrist_yaw_link" />
    <axis
      xyz="0 0 1" />
    <limit
      lower="-2.96"
      upper="2.96"
      effort="25"
      velocity="3.66" />
  </joint>

  <link name="left_wrist_pitch_link">
    <inertial>
      <origin xyz="0.00121060807931878 0.000367632697248155 1.31575604482848E-05" rpy="0 0 0" />
      <mass value="0.300586616809931" />
      <inertia
        ixx="7.19516793467273E-05" ixy="8.07499162509748E-08" ixz="3.86112841277518E-08"
        iyy="4.1882900811556E-05" iyz="-1.57821190035867E-07" izz="4.61879504954561E-05" />
    </inertial>
    <visual>
      <origin
        xyz="0 0 0"
        rpy="0 0 0" />
      <geometry>
        <mesh
          filename="../meshes/WRIST_UPDOWN_L.STL" />
      </geometry>
      <material
        name="">
        <color
          rgba="0.898039215686275 0.917647058823529 0.929411764705882 1" />
      </material>
    </visual>
     <!-- <collision>
      <origin
        xyz="0 0 0"
        rpy="0 0 0" />
      <geometry>
        <mesh
          filename="../meshes/WRIST_UPDOWN_L.STL" />
      </geometry>
    </collision> -->
  </link>
  <joint name="left_wrist_pitch_joint" type="fixed">
    <origin
      xyz="0 0 -0.20158"
      rpy="0 0 0" />
    <parent
      link="left_wrist_yaw_link" />
    <child
      link="left_wrist_pitch_link" />
    <axis
      xyz="0 1 0" />
    <limit
      lower="-1.57"
      upper="1.57"
      effort="7"
      velocity="3.66" />
  </joint>

  <link name="left_wrist_roll_link">
    <inertial>
      <origin xyz="0.00682932481897296 -0.000266254554519479 -0.123477452810365" rpy="0 0 0" />
      <mass value="0.664797816773533" />
      <inertia
        ixx="0.002" ixy="0.00" ixz="0.00"
        iyy="0.003" iyz="0.00" izz="0.001" />
    </inertial>
    <visual>
      <origin
        xyz="0 0 0"
        rpy="0 0 0" />
      <geometry>
        <mesh
          filename="../meshes/HAND_L.STL" />
      </geometry>
      <material
        name="">
        <color
          rgba="0.898039215686275 0.917647058823529 0.929411764705882 1" />
      </material>
    </visual>
     <collision>
      <origin
        xyz="0 0 0"
        rpy="0 0 0" />
      <geometry>
        <mesh
          filename="../meshes/HAND_L.STL" />
      </geometry>
    </collision>
  </link>
  <joint name="left_wrist_roll_joint" type="fixed">
    <origin
      xyz="0 0 0"
      rpy="0 0 0" />
    <parent
      link="left_wrist_pitch_link" />
    <child
      link="left_wrist_roll_link" />
    <axis
      xyz="1 0 0" />
    <limit
      lower="-1.57"
      upper="1.57"
      effort="7"
      velocity="3.66" />
  </joint>


  <!-- ************************************************************ -->
  <!-- ************************ Right Arm ************************** -->
  <!-- ************************************************************ -->
  <link name="right_shoulder_pitch_link">
    <inertial>
      <origin xyz="0.00400566910493358 -0.0697846247959809 -0.000414011813224091" rpy="0 0 0" />
      <mass value="1.26951093509678" />
      <inertia
        ixx="0.001" ixy="0.00" ixz="0.00"
        iyy="0.001" iyz="0.00" izz="0.001" />
    </inertial>
    <visual>
      <origin
        xyz="0 0 0"
        rpy="0 0 0" />
      <geometry>
        <mesh
          filename="../meshes/SCAPULA_R.STL" />
      </geometry>
      <material
        name="">
        <color
          rgba="0.698039215686274 0.698039215686274 0.698039215686274 1" />
      </material>
    </visual>
     <collision>
      <origin
        xyz="0 0 0"
        rpy="0 0 0" />
      <geometry>
        <mesh
          filename="../meshes/SCAPULA_R.STL" />
      </geometry>
    </collision>
  </link>
  <joint name="right_shoulder_pitch_joint" type="revolute">
    <origin
      xyz="0 -0.15869 0.29644"
      rpy="-0.34907 0 0" />
    <parent
      link="base_link" />
    <child
      link="right_shoulder_pitch_link" />
    <axis
      xyz="0 1 0" />
    <limit
      lower="-3.31"
      upper="1.22"
      effort="57"
      velocity="3.56" />
  </joint>

  <link name="right_shoulder_roll_link">
    <inertial>
      <origin xyz="-0.000187387954732679 -0.000796213076175029 -0.0823834087759314" rpy="0 0 0" />
      <mass value="1.38176034538629" />
      <inertia
        ixx="0.003" ixy="0.00" ixz="0.00"
        iyy="0.004" iyz="0.00" izz="0.001" />
    </inertial>
    <visual>
      <origin
        xyz="0 0 0"
        rpy="0 0 0" />
      <geometry>
        <mesh
          filename="../meshes/SHOULDER_R.STL" />
      </geometry>
      <material
        name="">
        <color
          rgba="0.698039215686274 0.698039215686274 0.698039215686274 1" />
      </material>
    </visual>
     <collision>
      <origin
        xyz="0 0 0"
        rpy="0 0 0" />
      <geometry>
        <mesh
          filename="../meshes/SHOULDER_R.STL" />
      </geometry>
    </collision>
  </link>
  <joint name="right_shoulder_roll_joint" type="revolute">
    <origin
      xyz="0 -0.075202 0"
      rpy="0.34907 0 0" />
    <parent
      link="right_shoulder_pitch_link" />
    <child
      link="right_shoulder_roll_link" />
    <axis
      xyz="1 0 0" />
    <limit
      lower="-3.14"
      upper="0.1"
      effort="57"
      velocity="3.56" />
  </joint>

  <link name="right_shoulder_yaw_link">
    <inertial>
      <origin xyz="-0.000150427974589584 -0.0013837454771512 -0.119529310769545" rpy="0 0 0" />
      <mass value="1.15167917389116" />
      <inertia
        ixx="0.003" ixy="0.00" ixz="0.00"
        iyy="0.003" iyz="0.00" izz="0.001" />
    </inertial>
    <visual>
      <origin
        xyz="0 0 0"
        rpy="0 0 0" />
      <geometry>
        <mesh
          filename="../meshes/UPPERARM_R.STL" />
      </geometry>
      <material
        name="">
        <color
          rgba="0.898039215686275 0.917647058823529 0.929411764705882 1" />
      </material>
    </visual>
     <collision>
      <origin
        xyz="0 0 0"
        rpy="0 0 0" />
      <geometry>
        <mesh
          filename="../meshes/UPPERARM_R.STL" />
      </geometry>
    </collision>
  </link>
  <joint name="right_shoulder_yaw_joint" type="revolute">
    <origin
      xyz="-1E-05 0 -0.0845"
      rpy="0 0 0" />
    <parent
      link="right_shoulder_roll_link" />
    <child
      link="right_shoulder_yaw_link" />
    <axis
      xyz="0 0 1" />
    <limit
      lower="-2.94"
      upper="2.94"
      effort="57"
      velocity="3.56" />
  </joint>

  <link name="right_elbow_link">
    <inertial>
      <origin xyz="-0.000517598306802938 0.000475828274850459 -0.0750122217350255" rpy="0 0 0" />
      <mass value="0.964265226005386" />
      <inertia
        ixx="0.002" ixy="0.00" ixz="0.00"
        iyy="0.002" iyz="0.00" izz="0.001" />
    </inertial>
    <visual>
      <origin
        xyz="0 0 0"
        rpy="0 0 0" />
      <geometry>
        <mesh
          filename="../meshes/FOREARM_R.STL" />
      </geometry>
      <material
        name="">
        <color
          rgba="0.898039215686275 0.917647058823529 0.929411764705882 1" />
      </material>
    </visual>
     <collision>
      <origin
        xyz="0 0 0"
        rpy="0 0 0" />
      <geometry>
        <mesh
          filename="../meshes/FOREARM_R.STL" />
      </geometry>
    </collision>
  </link>
  <joint name="right_elbow_joint" type="revolute">
    <origin
      xyz="0 0 -0.1455"
      rpy="0 0 0" />
    <parent
      link="right_shoulder_yaw_link" />
    <child
      link="right_elbow_link" />
    <axis
      xyz="0 1 0" />
    <limit
      lower="-2.09"
      upper="-0.2"
      effort="31"
      velocity="3.66" />
  </joint>

  <link name="right_wrist_yaw_link">
    <inertial>
      <origin xyz="0.000431441811552552 -0.000950548685657721 -0.105249650721468" rpy="0 0 0" />
      <mass value="0.807080212201238" />
      <inertia
        ixx="0.003" ixy="0.00" ixz="0.00"
        iyy="0.002" iyz="0.00" izz="0.001" />
    </inertial>
    <visual>
      <origin
        xyz="0 0 0"
        rpy="0 0 0" />
      <geometry>
        <mesh
          filename="../meshes/WRIST_REVOLUTE_R.STL" />
      </geometry>
      <material
        name="">
        <color
          rgba="0.898039215686275 0.917647058823529 0.929411764705882 1" />
      </material>
    </visual>
     <collision>
      <origin
        xyz="0 0 0"
        rpy="0 0 0" />
      <geometry>
        <mesh
          filename="../meshes/WRIST_REVOLUTE_R.STL" />
      </geometry>
    </collision>
  </link>
  <joint name="right_wrist_yaw_joint" type="fixed">
    <origin
      xyz="0 0 -0.068424"
      rpy="0 0 0" />
    <parent
      link="right_elbow_link" />
    <child
      link="right_wrist_yaw_link" />
    <axis
      xyz="0 0 1" />
    <limit
      lower="-2.96"
      upper="2.96"
      effort="25"
      velocity="3.66" />
  </joint>

  <link name="right_wrist_pitch_link">
    <inertial>
      <origin xyz="0.0012106037788502 -0.000409146062765847 -2.30692765414986E-05" rpy="0 0 0" />
      <mass value="0.300585798923164" />
      <inertia
        ixx="7.19512926025205E-05" ixy="-1.5038820487215E-07" ixz="-3.31399908676816E-08"
        iyy="4.18864352400047E-05" iyz="1.61671879913588E-07" izz="4.61837999641859E-05" />
    </inertial>
    <visual>
      <origin
        xyz="0 0 0"
        rpy="0 0 0" />
      <geometry>
        <mesh
          filename="../meshes/WRIST_UPDOWN_R.STL" />
      </geometry>
      <material
        name="">
        <color
          rgba="0.811764705882353 1 0.980392156862745 1" />
      </material>
    </visual>
     <!-- <collision>
      <origin
        xyz="0 0 0"
        rpy="0 0 0" />
      <geometry>
        <mesh
          filename="../meshes/WRIST_UPDOWN_R.STL" />
      </geometry>
    </collision> -->
  </link>
  <joint name="right_wrist_pitch_joint" type="fixed">
    <origin
      xyz="0 0 -0.20158"
      rpy="0 0 0" />
    <parent
      link="right_wrist_yaw_link" />
    <child
      link="right_wrist_pitch_link" />
    <axis
      xyz="0 1 0" />
    <limit
      lower="-1.57"
      upper="1.57"
      effort="7"
      velocity="3.66" />
  </joint>

  <link name="right_wrist_roll_link">
    <inertial>
      <origin xyz="0.00704233256805226 -0.000160093721480153 -0.12352503949791" rpy="0 0 0" />
      <mass value="0.664607012887281" />
      <inertia
        ixx="0.002" ixy="-1.41468504761944E-06" ixz="9.32067541347773E-06"
        iyy="0.003" iyz="-1.39063938994495E-06" izz="0.001" />
    </inertial>
    <visual>
      <origin
        xyz="0 0 0"
        rpy="0 0 0" />
      <geometry>
        <mesh
          filename="../meshes/HAND_R.STL" />
      </geometry>
      <material
        name="">
        <color
          rgba="0.898039215686275 0.917647058823529 0.929411764705882 1" />
      </material>
    </visual>
     <collision>
      <origin
        xyz="0 0 0"
        rpy="0 0 0" />
      <geometry>
        <mesh
          filename="../meshes/HAND_R.STL" />
      </geometry>
    </collision>
  </link>
  <joint name="right_wrist_roll_joint" type="fixed">
    <origin
      xyz="0 0 0"
      rpy="0 0 0" />
    <parent
      link="right_wrist_pitch_link" />
    <child
      link="right_wrist_roll_link" />
    <axis
      xyz="1 0 0" />
    <limit
      lower="-1.57"
      upper="1.57"
      effort="7"
      velocity="3.66" />
  </joint>

  <!-- ************************************************************ -->
  <!-- ************************ Waist ************************** -->
  <!-- ************************************************************ -->

  <link name="waist_link">
    <inertial>
      <origin xyz="0.000349547087776611 6.72203982574754E-06 -0.0507127555650615" rpy="0 0 0" />
      <mass value="3.02215535624108" />
      <inertia ixx="0.010" ixy="0.0" ixz="0.0"
               iyy="0.004" iyz="0.0" izz="0.011" />
    </inertial>
    <visual>
      <origin xyz="0 0 0" rpy="0 0 0" />
      <geometry>
        <mesh filename="../meshes/SACRUM.STL" />
      </geometry>
      <material name="">
        <color rgba="0.498039215686275 0.498039215686275 0.498039215686275 1" />
      </material>
    </visual>
     <!-- <collision>
      <origin
        xyz="0 0 0"
        rpy="0 0 0" />
      <geometry>
        <mesh
          filename="../meshes/SACRUM.STL" />
      </geometry>
    </collision> -->
  </link>

  <joint name="waist_joint" type="revolute">
    <origin xyz="0 0 -0.0691" rpy="0 0 0" />
    <parent link="base_link" />
    <child link="waist_link" />
    <axis xyz="0 0 1" />
    <limit lower="-0.523"
            upper="0.523"
            effort="96"
            velocity="12.21" />
  </joint>

  <!-- ************************************************************ -->
  <!-- ************************ Left Leg ************************** -->
  <!-- ************************************************************ -->

  <!-- ************* left hip yaw link *************** -->
  <link name="left_hip_yaw_link">
    <inertial>
      <origin
        xyz="-0.097564 0.035504 0.0082709"
        rpy="0 0 0" />
      <mass
        value="2.8128" />
      <inertia
        ixx="0.006" ixy="-0.001" ixz="0.002"
        iyy="0.012" iyz="0.00" izz="0.011" />
    </inertial>
    <visual>
      <origin
        xyz="0 0 0"
        rpy="0 0 0" />
      <geometry>
        <mesh
          filename="../meshes/ILIUM_L.STL" />
      </geometry>
      <material
        name="">
        <color
          rgba="0.89804 0.91765 0.92941 1" />
      </material>
    </visual>
     <!-- <collision>
      <origin
        xyz="0 0 0"
        rpy="0 0 0" />
      <geometry>
        <mesh
          filename="../meshes/ILIUM_L.STL" />
      </geometry>
    </collision> -->
  </link>
  <joint name="left_hip_yaw_joint"
    type="revolute">
    <origin
      xyz="0 0.051 -0.1698"
      rpy="0 0 0" />
    <parent
      link="waist_link" />
    <child
      link="left_hip_yaw_link" />
    <axis
      xyz="0 0 1" />
    <limit
      lower="-0.15"
      upper="0.15"
      effort="96"
      velocity="12.21" />
  </joint>

  <!-- ************* left hip roll link *************** -->
  <link name="left_hip_roll_link">
    <inertial>
      <origin
        xyz="-0.00378118871227864 -0.0186369651990369 -0.000334508880895035"
        rpy="0 0 0" />
      <mass
        value="2.54211026639439" />
      <inertia
        ixx="0.004" ixy="0.00" ixz="0.00"
        iyy="0.005" iyz="0.00" izz="0.004" />
    </inertial>
    <visual>
      <origin
        xyz="0 0 0"
        rpy="0 0 0" />
      <geometry>
        <mesh
          filename="../meshes/ISCHIUM_L.STL" />
      </geometry>
      <material
        name="">
        <color
          rgba="0.898039215686275 0.917647058823529 0.929411764705882 1" />
      </material>
    </visual>
     <!-- <collision>
      <origin
        xyz="0 0 0"
        rpy="0 0 0" />
      <geometry>
        <mesh
          filename="../meshes/ISCHIUM_L.STL" />
      </geometry>
    </collision> -->
  </link>
  <joint name="left_hip_roll_joint"
    type="revolute">
    <origin
      xyz="0 0.0375 0"
      rpy="0 0 0" />
    <parent
      link="left_hip_yaw_link" />
    <child
      link="left_hip_roll_link" />
    <axis
      xyz="1 0 0" />
    <limit
      lower="-0.436"
      upper="0.436"
      effort="216"
      velocity="10.47" />
  </joint>

  <!-- ************* left hip pitch link *************** -->
  <link name="left_hip_pitch_link">
    <inertial>
      <origin
        xyz="0.00486744936008764 0.0229267112286704 -0.041636516186895"
        rpy="0 0 0" />
      <mass
        value="2.95253119232822" />
      <inertia
        ixx="0.03" ixy="0.00" ixz="-0.002"
        iyy="0.03" iyz="0.001" izz="0.005" />
    </inertial>
    <visual>
      <origin
        xyz="0 0 0"
        rpy="0 0 0" />
      <geometry>
        <mesh
          filename="../meshes/THIGH_L.STL" />
      </geometry>
      <material
        name="">
        <color
          rgba="0.898039215686275 0.917647058823529 0.929411764705882 1" />
      </material>
    </visual>
     <collision>
      <origin
        xyz="0 0 0"
        rpy="0 0 0" />
      <geometry>
        <mesh
          filename="../meshes/THIGH_L.STL" />
      </geometry>
    </collision>
  </link>
  <joint name="left_hip_pitch_joint" type="revolute">
    <origin
      xyz="0 0.043004 0"
      rpy="0 0 0" />
    <parent
      link="left_hip_roll_link" />
    <child
      link="left_hip_pitch_link" />
    <axis
      xyz="0 1 0" />
    <limit
      lower="-2.0"
      upper="0.436"
      effort="216"
      velocity="10.47" />
  </joint>

  <!-- *************left knee link *************** -->
  <link name="left_knee_link">
    <inertial>
      <origin xyz="0.0111437713714776 0.0075144171292757 -0.0718395109013203" rpy="0 0 0" />
      <mass value="2.28347565956066" />
      <inertia
        ixx="0.02" ixy="0.000" ixz="0.000"
        iyy="0.02" iyz="0.001" izz="0.002" />
    </inertial>
    <visual>
      <origin
        xyz="0 0 0"
        rpy="0 0 0" />
      <geometry>
        <mesh
          filename="../meshes/SHANK_L.STL" />
      </geometry>
      <material
        name="">
        <color
          rgba="0.898039215686275 0.917647058823529 0.929411764705882 1" />
      </material>
    </visual>
     <!-- <collision>
      <origin
        xyz="0 0 0"
        rpy="0 0 0" />
      <geometry>
        <mesh
          filename="../meshes/SHANK_L.STL" />
      </geometry>
    </collision> -->
    <!-- <collision>
      <origin xyz="0.035 0 -0.16"/>
      <geometry>
        <cylinder radius="0.045" length="0.2" />
      </geometry>
    </collision> -->
  </link>
  <joint name="left_knee_joint"
    type="revolute">
    <origin
      xyz="0 0 -0.34"
      rpy="0 0 0" />
    <parent
      link="left_hip_pitch_link" />
    <child
      link="left_knee_link" />
    <axis
      xyz="0 1 0" />
    <limit
      lower="0.3"
      upper="2.0"
      effort="216"
      velocity="10.47" />
  </joint>

  <!-- ************* left ankle pitch link *************** -->
  <link name="left_ankle_pitch_link">
    <inertial>
      <origin xyz="0.00246209233657717 5.93317442537933E-05 -1.23145407759928E-07" rpy="0 0 0" />
      <mass value="0.0540428010832722" />
      <inertia
        ixx="4.09614233280902E-06" ixy="5.93504902113906E-11" ixz="-7.79724250402226E-11"
        iyy="7.67425544057315E-06" iyz="2.10288280962253E-11" izz="8.59958974753414E-06" />
    </inertial>
    <visual>
      <origin
        xyz="0 0 0"
        rpy="0 0 0" />
      <geometry>
        <mesh
          filename="../meshes/ASTRAGALUS_L.STL" />
      </geometry>
      <material
        name="">
        <color
          rgba="0.529411764705882 0.549019607843137 0.549019607843137 1" />
      </material>
    </visual>
     <!-- <collision>
      <origin
        xyz="0 0 0"
        rpy="0 0 0" />
      <geometry>
        <mesh
          filename="../meshes/ASTRAGALUS_L.STL" />
      </geometry>
    </collision> -->
  </link>
  <joint name="left_ankle_pitch_joint" type="revolute">
    <origin
      xyz="0 0 -0.36"
      rpy="0 0 0" />
    <parent
      link="left_knee_link" />
    <child
      link="left_ankle_pitch_link" />
    <axis
      xyz="0 1 0" />
    <limit
      lower="-0.698"
      upper="0.525"
      effort="40"
      velocity="12.56" />
  </joint>

  <!-- ************* left ankle roll link *************** -->
  <link name="left_ankle_roll_link">
    <inertial>
      <origin
        xyz="0.0173378971382406 0.000446493080629981 -0.0526985178808428"
        rpy="0 0 0" />
      <mass
        value="0.669297710196622" />
      <inertia
        ixx="0.000265846142331934"
        ixy="1.98211949368065E-05"
        ixz="1.25416614346479E-05"
        iyy="0.00143885589573861"
        iyz="-3.15941982128854E-06"
        izz="0.00165348852732234" />
    </inertial>
    <visual>
      <origin
        xyz="0 0 0"
        rpy="0 0 0" />
      <geometry>
        <mesh
          filename="../meshes/FOOT_L.STL" />
      </geometry>
      <material
        name="">
        <color
          rgba="0.792156862745098 0.819607843137255 0.933333333333333 1" />
      </material>
    </visual>
     <collision>
      <origin
        xyz="0 0 0"
        rpy="0 0 0" />
      <geometry>
        <mesh
          filename="../meshes/FOOT_L.STL" />
      </geometry>
    </collision>
  </link>
  <joint name="left_ankle_roll_joint" type="revolute">
    <origin
      xyz="0 0 0"
      rpy="0 0 0" />
    <parent
      link="left_ankle_pitch_link" />
    <child
      link="left_ankle_roll_link" />
    <axis
      xyz="1 0 0" />
    <limit
      lower="-0.331"
      upper="0.331"
      effort="40"
      velocity="12.56" />
  </joint>

  <!-- ************************************************************ -->
  <!-- ************************ Right Leg ************************** -->
  <!-- ************************************************************ -->

  <!-- ************* right hip yaw link *************** -->
 <link name="right_hip_yaw_link">
    <inertial>
      <origin xyz="-0.0975642590819654 -0.0354786240384467 0.00831189475838978" rpy="0 0 0" />
      <mass value="2.81278353129309" />
      <inertia
        ixx="0.006" ixy="0.001" ixz="0.002"
        iyy="0.012" iyz="0.00" izz="0.011" />
    </inertial>
    <visual>
      <origin
        xyz="0 0 0"
        rpy="0 0 0" />
      <geometry>
        <mesh
          filename="../meshes/ILIUM_R.STL" />
      </geometry>
      <material
        name="">
        <color
          rgba="0.43921568627451 0.43921568627451 0.43921568627451 1" />
      </material>
    </visual>
     <!-- <collision>
      <origin
        xyz="0 0 0"
        rpy="0 0 0" />
      <geometry>
        <mesh
          filename="../meshes/ILIUM_R.STL" />
      </geometry>
    </collision> -->
  </link>
  <joint name="right_hip_yaw_joint" type="revolute">
    <origin
      xyz="0 -0.051 -0.1698"
      rpy="0 0 0" />
    <parent
      link="waist_link" />
    <child
      link="right_hip_yaw_link" />
    <axis
      xyz="0 0 1" />
    <limit
      lower="-0.15"
      upper="0.15"
      effort="96"
      velocity="12.2" />
  </joint>

  <!-- ************* right hip roll link *************** -->
  <link name="right_hip_roll_link">
    <inertial>
      <origin xyz="-0.00365073330205207 0.0186699920885547 -0.00020850293107344" rpy="0 0 0" />
      <mass
        value="2.53761330127982" />
      <inertia
        ixx="0.003" ixy="0.00" ixz="0.00"
        iyy="0.005" iyz="0.00" izz="0.004" />
    </inertial>
    <visual>
      <origin
        xyz="0 0 0"
        rpy="0 0 0" />
      <geometry>
        <mesh
          filename="../meshes/ISCHIUM_R.STL" />
      </geometry>
      <material
        name="">
        <color
          rgba="0.792156862745098 0.819607843137255 0.933333333333333 1" />
      </material>
    </visual>
     <!-- <collision>
      <origin
        xyz="0 0 0"
        rpy="0 0 0" />
      <geometry>
        <mesh
          filename="../meshes/ISCHIUM_R.STL" />
      </geometry>
    </collision> -->
  </link>
  <joint name="right_hip_roll_joint" type="revolute">
    <origin
      xyz="0 -0.0375 0"
      rpy="0 0 0" />
    <parent
      link="right_hip_yaw_link" />
    <child
      link="right_hip_roll_link" />
    <axis
      xyz="1 0 0" />
    <limit
      lower="-0.436"
      upper="0.436"
      effort="216"
      velocity="10.47" />
  </joint>

  <!-- ************* right hip pitch link *************** -->
  <link name="right_hip_pitch_link">
    <inertial>
      <origin xyz="0.004891612004919 -0.0230654581131054 -0.0408628057143543" rpy="0 0 0" />
      <mass value="2.94365654752782" />
      <inertia
        ixx="0.029" ixy="0.00" ixz="-0.002"
        iyy="0.03" iyz="-0.001" izz="0.005" />
    </inertial>
    <visual>
      <origin
        xyz="0 0 0"
        rpy="0 0 0" />
      <geometry>
        <mesh
          filename="../meshes/THIGH_R.STL" />
      </geometry>
      <material
        name="">
        <color
          rgba="1 1 1 1" />
      </material>
    </visual>
     <collision>
      <origin
        xyz="0 0 0"
        rpy="0 0 0" />
      <geometry>
        <mesh
          filename="../meshes/THIGH_R.STL" />
      </geometry>
    </collision>
  </link>
  <joint name="right_hip_pitch_joint" type="revolute">
    <origin
      xyz="0 -0.043004 0"
      rpy="0 0 0" />
    <parent
      link="right_hip_roll_link" />
    <child
      link="right_hip_pitch_link" />
    <axis
      xyz="0 1 0" />
    <limit
      lower="-2.0"
      upper="0.436"
      effort="216"
      velocity="10.47" />
  </joint>

  <!-- ************* right knee link *************** -->
  <link name="right_knee_link">
    <inertial>
      <origin
        xyz="0.0110809570415845 -0.00748587626913599 -0.0719839927543433"
        rpy="0 0 0" />
      <mass
        value="2.27927601326776" />
      <inertia
        ixx="0.02" ixy="0.00" ixz="0.00"
        iyy="0.02" iyz="-0.001" izz="0.002" />
    </inertial>
    <visual>
      <origin
        xyz="0 0 0"
        rpy="0 0 0" />
      <geometry>
        <mesh
          filename="../meshes/SHANK_R.STL" />
      </geometry>
      <material
        name="">
        <color
          rgba="0.898039215686275 0.917647058823529 0.929411764705882 1" />
      </material>
    </visual>
     <!-- <collision>
      <origin
        xyz="0 0 0"
        rpy="0 0 0" />
      <geometry>
        <mesh
          filename="../meshes/SHANK_R.STL" />
      </geometry>
    </collision> -->
    <!-- <collision>
      <origin xyz="0.035 0 -0.16"/>
      <geometry>
        <cylinder radius="0.045" length="0.2" />
      </geometry>
    </collision> -->
  </link>
  <joint name="right_knee_joint"
    type="revolute">
    <origin
      xyz="0 0 -0.34"
      rpy="0 0 0" />
    <parent
      link="right_hip_pitch_link" />
    <child
      link="right_knee_link" />
    <axis
      xyz="0 1 0" />
    <limit
      lower="0.3"
      upper="2.0"
      effort="216"
      velocity="10.47" />
  </joint>

  <!-- ************* right ankle pitch link *************** -->
  <link name="right_ankle_pitch_link">
    <inertial>
      <origin
        xyz="0.00246209233657721 5.9176010104689E-05 1.23145407426861E-07"
        rpy="0 0 0" />
      <mass
        value="0.0540428010832721" />
      <inertia
        ixx="4.096142332809E-06" ixy="-5.93504903780132E-11" ixz="7.79724248693916E-11"
        iyy="7.67425544057305E-06" iyz="2.10288280946885E-11" izz="8.59958974753404E-06" />
    </inertial>
    <visual>
      <origin
        xyz="0 0 0"
        rpy="0 0 0" />
      <geometry>
        <mesh
          filename="../meshes/ASTRAGALUS_R.STL" />
      </geometry>
      <material
        name="">
        <color
          rgba="0.529411764705882 0.549019607843137 0.549019607843137 1" />
      </material>
    </visual>
     <!-- <collision>
      <origin
        xyz="0 0 0"
        rpy="0 0 0" />
      <geometry>
        <mesh
          filename="../meshes/ASTRAGALUS_R.STL" />
      </geometry>
    </collision> -->
  </link>
  <joint name="right_ankle_pitch_joint" type="revolute">
    <origin
      xyz="0 0 -0.36"
      rpy="0 0 0" />
    <parent
      link="right_knee_link" />
    <child
      link="right_ankle_pitch_link" />
    <axis
      xyz="0 1 0" />
    <limit
      lower="-0.698"
      upper="0.525"
      effort="40"
      velocity="12.56" />
  </joint>

  <!-- ************* right ankle roll link *************** -->
  <link name="right_ankle_roll_link">
    <inertial>
      <origin
        xyz="0.0172182308455084 -0.000490155366929923 -0.0526971717477904"
        rpy="0 0 0" />
      <mass
        value="0.66921361169682" />
      <inertia
        ixx="0.001" ixy="0.00" ixz="0.00"
        iyy="0.002" iyz="0.00" izz="0.002" />
    </inertial>
    <visual>
      <origin
        xyz="0 0 0"
        rpy="0 0 0" />
      <geometry>
        <mesh
          filename="../meshes/FOOT_R.STL" />
      </geometry>
      <material
        name="">
        <color
          rgba="1 1 1 1" />
      </material>
    </visual>
     <collision>
      <origin
        xyz="0 0 0"
        rpy="0 0 0" />
      <geometry>
        <mesh
          filename="../meshes/FOOT_R.STL" />
      </geometry>
    </collision>
  </link>
  <joint name="right_ankle_roll_joint"
    type="revolute">
    <origin
      xyz="0 0 0"
      rpy="0 0 0" />
    <parent
      link="right_ankle_pitch_link" />
    <child
      link="right_ankle_roll_link" />
    <axis
      xyz="1 0 0" />
    <limit
      lower="-0.331"
      upper="0.331"
      effort="40"
      velocity="12.56" />
  </joint>


  <!-- ************************************************************ -->
  <!-- ************************ Neck ************************** -->
  <!-- ************************************************************ -->
  <link
    name="neck_yaw_link">
    <inertial>
      <origin
        xyz="2.5298E-06 0.00054416 0.039066"
        rpy="0 0 0" />
      <mass
        value="0.31299" />
      <inertia
        ixx="5.1138E-05"
        ixy="-4.0141E-09"
        ixz="1.2204E-08"
        iyy="7.8331E-05"
        iyz="3.4878E-06"
        izz="4.6855E-05" />
    </inertial>
    <visual>
      <origin
        xyz="0 0 0"
        rpy="0 0 0" />
      <geometry>
        <mesh
          filename="../meshes/NECK.STL" />
      </geometry>
      <material
        name="">
        <color
          rgba="0.69804 0.69804 0.69804 1" />
      </material>
    </visual>
     <!-- <collision>
      <origin
        xyz="0 0 0"
        rpy="0 0 0" />
      <geometry>
        <mesh
          filename="../meshes/NECK.STL" />
      </geometry>
    </collision> -->
  </link>

  <joint name="neck_yaw_joint" type="fixed">
    <origin xyz="0 0 0.43204" rpy="0 0 0" />
    <parent
      link="base_link" />
    <child
      link="neck_yaw_link" />
    <axis
      xyz="0 0 1" />
    <limit
      lower="-0.785"
      upper="0.785"
      effort="7"
      velocity="3.62" />
  </joint>

  <link name="neck_pitch_link">
    <inertial>
      <origin xyz="0.014618 -0.0011212 0.065974" rpy="0 0 0" />
      <mass
        value="0.67892" />
      <inertia
        ixx="0.00084994"
        ixy="-1.5203E-06"
        ixz="-1.8888E-05"
        iyy="0.00073044"
        iyz="-8.2217E-06"
        izz="0.00088165" />
    </inertial>
    <visual>
      <origin
        xyz="0 0 0"
        rpy="0 0 0" />
      <geometry>
        <mesh
          filename="../meshes/HEAD.STL" />
      </geometry>
      <material
        name="">
        <color
          rgba="0.38431 0.41176 0.45098 1" />
      </material>
    </visual>
     <!-- <collision>
      <origin
        xyz="0 0 0"
        rpy="0 0 0" />
      <geometry>
        <mesh
          filename="../meshes/HEAD.STL" />
      </geometry>
    </collision> -->
  </link>
  <joint
    name="neck_pitch_joint"
    type="fixed">
    <origin
      xyz="0 0 0.042"
      rpy="0 0 0" />
    <parent
      link="neck_yaw_link" />
    <child
      link="neck_pitch_link" />
    <axis
      xyz="0 1 0" />
    <limit
      lower="-0.174"
      upper="0.349"
      effort="7"
      velocity="3.62" />
  </joint>
</robot>